Workbook

Sheet final
A1: Entity | B1: Primary energy consumption per capita | C1: Value_co2_emissions_kt_by_country | D1: Electricity from fossil fuels | E1: Electricity from renewables | F1: Low-carbon electricity | G1: Density | H1: Access to electricity | I1: Renewables | J1: gdp_growth | K1: gdp_per_capita | L1: Energy imports
A2: Algeria | B2: 16259.053 | C2: 171250 | D2: 75.85 | E2: 0.84 | F2: 1.0953188 | G2: 18 | H2: 99.5 | I2: 0.29474697 | J2: 1 | K2: 3989.6683 | L2: -133.35275
A3: Argentina | B3: 20725.168 | C3: 168100.01 | D3: 90.56 | E3: 34.63 | F3: 31.991589 | G3: 17 | H3: 100 | I3: 11.926772 | J3: -2.0259342 | K3: 10056.638 | L3: 2.4916771
A4: Australia | B4: 66263.54 | C4: 386530 | D4: 196.45 | E4: 53.41 | F4: 21.37597 | G4: 3 | H4: 100 | I4: 8.880722 | J4: 2.1131494 | K4: 54875.286 | L4: -230.54025
A5: Austria | B5: 48314.258 | C5: 64769.997 | D5: 16.22 | E5: 54.64 | F5: 77.109795 | G5: 109 | H5: 100 | I5: 35.611378 | J5: 1.4912109 | K5: 50114.401 | L5: 74.476282
A6: Azerbaijan | B6: 17546.781 | C6: 35509.998 | D6: 22.91 | E6: 1.69 | F6: 6.869919 | G6: 123 | H6: 100 | I6: 2.674584 | J6: 2.5 | K6: 4805.7537 | L6: -274.41746
A7: Bangladesh | B7: 2916.3176 | C7: 90739.998 | D7: 78.37 | E7: 1.14 | F7: 1.4337819 | G7: 1265 | H7: 92.2 | I7: 0.6751287 | J7: 8.1526841 | K7: 1855.7401 | L7: 30.297494
A8: Belarus | B8: 31923.436 | C8: 57669.998 | D8: 36.74 | E8: 0.94 | F8: 2.494692 | G8: 47 | H8: 100 | I8: 0.70776963 | J8: 1.4 | K8: 6837.7178 | L8: 85.255535
A9: Belgium | B9: 64152.26 | C9: 93010.002 | D9: 29.32 | E9: 19.47 | F9: 68.237465 | G9: 383 | H9: 100 | I9: 7.959382 | J9: 2.1495597 | K9: 46591.492 | L9: 90.930226
A10: Brazil | B10: 16681.945 | C10: 434299.99 | D10: 90.91 | E10: 512.59 | F10: 85.30534 | G10: 25 | H10: 99.8 | I10: 47.304844 | J10: 1.411153 | K10: 8897.553 | L10: -4.0596361
A11: Bulgaria | B11: 29996.027 | C11: 39139.999 | D11: 19.75 | E11: 7.49 | F11: 54.908676 | G11: 64 | H11: 100 | I11: 9.948385 | J11: 4.0375921 | K11: 9879.2685 | L11: 39.323183
A12: Canada | B12: 107980.76 | C12: 580210.02 | D12: 110.65 | E12: 421.8 | F12: 82.378334 | G12: 4 | H12: 100 | I12: 28.586376 | J12: 1.879592 | K12: 46338.341 | L12: -75.769176
A13: Chile | B13: 24894.514 | C13: 91370.003 | D13: 45.16 | E13: 32.23 | F13: 41.64621 | G13: 26 | H13: 100 | I13: 24.144995 | J13: 0.94200531 | K13: 14741.714 | L13: 69.225887
... A64: Uzbekistan | B64: 16212.221 | C64: 116710 | D64: 53.64 | E64: 6.47 | F64: 10.7636 | G64: 79 | H64: 100 | I64: 3.1970327 | J64: 5.7096322 | K64: 1784.0098 | L64: -19.679857

Sheet disp_for_r
A1: Value_co2_emissions_kt_by_country | B1: Density
A2: 386530 | B2: 3-31
A3: 580210.02 | B3: 3-31
A4: 212110 | B4: 3-31
A5: 35950.001 | B5: 3-31
A6: 76029.999 | B6: 3-31
A7: 523780.03 | B7: 3-31
A8: 168100.01 | B8: 3-31
A9: 171250 | B9: 3-31
A10: 40709.999 | B10: 3-31
A11: 34009.998 | B11: 3-31
A12: 434299.99 | B12: 3-31
A13: 35000 | B13: 3-31
... A64: 47380.001 | B64: 219-8358

Sheet disp_res
A1: Однофакторный дисперсионный анализ
A3: ИТОГИ
A4: Группы | B4: Счет | C4: Сумма | D4: Среднее | E4: Дисперсия
A5: 3-31 | B5: 16 | C5: 2863850 | D5: 178990.63 | E5: 3.7455036e+10
A6: 36-93 | B6: 16 | C6: 6593550.2 | D6: 412096.89 | E6: 1.3990955e+12
A7: 94-206 | B7: 15 | C7: 13423750 | D7: 894916.65 | E7: 7.3952202e+12
A8: 219-8358 | B8: 16 | C8: 5568980 | D8: 348061.25 | E8: 3.9596909e+11
A11: Дисперсионный анализ
A12: Источник вариации | B12: SS | C12: df | D12: MS | E12: F | F12: P-Значение | G12: F критическое
A13: Между группами | B13: 4.333491e+12 | C13: 3 | D13: 1.444497e+12 | E13: 0.65047132 | F13: 0.58580662 | G13: 2.760767
A14: Внутри групп | B14: 1.3102088e+14 | C14: 59 | D14: 2.2206928e+12
A16: Итого | B16: 1.3535437e+14 | C16: 62

Sheet for_disp
A1: 3-31 | B1: 36-93 | C1: 94-206 | D1: 219-8358
A2: 386530 | B2: 4817720.2 | C2: 239980 | D2: 37380.001
A3: 580210.02 | B3: 11730 | C3: 253270 | D3: 657400.02
A4: 212110 | B4: 81040.001 | C4: 13600 | D4: 92650.002
A5: 35950.001 | B5: 57669.998 | C5: 46380.001 | D5: 9489.9998
A6: 76029.999 | B6: 439640.01 | C6: 64769.997 | D6: 91970.001
A7: 523780.03 | B7: 39139.999 | C7: 44639.999 | D7: 17190.001
A8: 168100.01 | B8: 449269.99 | C8: 188860 | D8: 348920.01
A9: 171250 | B9: 39290.001 | C9: 300519.99 | D9: 190570.01
A10: 40709.999 | B10: 16520 | C10: 35509.998 | D10: 1081569.9
A11: 34009.998 | B11: 35750 | C11: 295130 | D11: 145420
A12: 434299.99 | B12: 174730 | C12: 29700.001 | D12: 93010.002
A13: 35000 | B13: 116710 | C13: 267090 | D13: 62650.002
... A16: 7570.0002 | B16: 8300.0002 | C16: 317239.99 | D16: 90739.998
A17: 10180 | B17: 174560 | D17: 47380.001

Sheet energy
A1: Entity | B1: Year | C1: Primary energy consumption per capita (kWh/person) | D1: Value_co2_emissions_kt_by_country | E1: Electricity from fossil fuels (TWh) | F1: Electricity from nuclear (TWh) | G1: Electricity from renewables (TWh) | H1: Low-carbon electricity (% electricity) | I1: Renewable-electricity-generating-capacity-per-capita | J1: Renewable energy share in the total final energy consumption (%) | K1: Density\n(P/Km2) | L1: Access to electricity (% of population) | M1: Access to clean fuels for cooking | N1: Renewables (% equivalent primary energy) | O1: Financial flows to developing countries (US $) | P1: gdp_growth | Q1: gdp_per_capita | R1: Energy intensity level of primary energy (MJ/$2017 PPP GDP) | S1: Land Area(Km2) | T1: Latitude | U1: Longitude | V1: Energy imports, net (% of energy use)
A2: Afghanistan | B2: 2000 | C2: 302.59482 | D2: 760 | E2: 0.16 | F2: 0 | G2: 0.31 | H2: 65.95744 | I2: 9.22 | J2: 44.99 | K2: 60 | L2: 1.613591 | M2: 6.2 | O2: 20000 | R2: 1.64 | S2: 652230 | T2: 33.93911 | U2: 67.709953
A3: Afghanistan | B3: 2001 | C3: 236.89185 | D3: 730 | E3: 0.09 | F3: 0 | G3: 0.5 | H3: 84.745766 | I3: 8.86 | J3: 45.6 | K3: 60 | L3: 4.074574 | M3: 7.2 | O3: 130000 | R3: 1.74 | S3: 652230 | T3: 33.93911 | U3: 67.709953
A4: Afghanistan | B4: 2002 | C4: 210.86215 | D4: 1030 | E4: 0.13 | F4: 0 | G4: 0.56 | H4: 81.159424 | I4: 8.47 | J4: 37.83 | K4: 60 | L4: 9.409158 | M4: 8.2 | O4: 3950000 | Q4: 179.42658 | R4: 1.4 | S4: 652230 | T4: 33.93911 | U4: 67.709953
A5: Afghanistan | B5: 2003 | C5: 229.96822 | D5: 1220 | E5: 0.31 | F5: 0 | G5: 0.63 | H5: 67.02128 | I5: 8.09 | J5: 36.66 | K5: 60 | L5: 14.738506 | M5: 9.5 | O5: 25970000 | P5: 8.8322778 | Q5: 190.68381 | R5: 1.4 | S5: 652230 | T5: 33.93911 | U5: 67.709953
A6: Afghanistan | B6: 2004 | C6: 204.23125 | D6: 1030 | E6: 0.33 | F6: 0 | G6: 0.56 | H6: 62.92135 | I6: 7.75 | J6: 44.24 | K6: 60 | L6: 20.064968 | M6: 10.9 | P6: 1.414118 | Q6: 211.38207 | R6: 1.2 | S6: 652230 | T6: 33.93911 | U6: 67.709953
A7: Afghanistan | B7: 2005 | C7: 252.06912 | D7: 1550 | E7: 0.34 | F7: 0 | G7: 0.59 | H7: 63.440857 | I7: 7.51 | J7: 33.88 | K7: 60 | L7: 25.390894 | M7: 12.2 | O7: 9830000 | P7: 11.229715 | Q7: 242.03131 | R7: 1.41 | S7: 652230 | T7: 33.93911 | U7: 67.709953
A8: Afghanistan | B8: 2006 | C8: 304.4209 | D8: 1760 | E8: 0.2 | F8: 0 | G8: 0.64 | H8: 76.190475 | I8: 7.4 | J8: 31.89 | K8: 60 | L8: 30.71869 | M8: 13.85 | O8: 10620000 | P8: 5.3574033 | Q8: 263.7336 | R8: 1.5 | S8: 652230 | T8: 33.93911 | U8: 67.709953
A9: Afghanistan | B9: 2007 | C9: 354.2799 | D9: 1770 | E9: 0.2 | F9: 0 | G9: 0.75 | H9: 78.94737 | I9: 7.25 | J9: 28.78 | K9: 60 | L9: 36.05101 | M9: 15.3 | O9: 15750000 | P9: 13.82632 | Q9: 359.69316 | R9: 1.53 | S9: 652230 | T9: 33.93911 | U9: 67.709953
A10: Afghanistan | B10: 2008 | C10: 607.8335 | D10: 3559.9999 | E10: 0.19 | F10: 0 | G10: 0.54 | H10: 73.9726 | I10: 7.49 | J10: 21.17 | K10: 60 | L10: 42.4 | M10: 16.7 | O10: 16170000 | P10: 3.9249838 | Q10: 364.66354 | R10: 1.94 | S10: 652230 | T10: 33.93911 | U10: 67.709953
A11: Afghanistan | B11: 2009 | C11: 975.04816 | D11: 4880.0001 | E11: 0.16 | F11: 0 | G11: 0.78 | H11: 82.97872 | I11: 7.5 | J11: 16.53 | K11: 60 | L11: 46.74005 | M11: 18.4 | O11: 9960000 | P11: 21.390528 | Q11: 437.26874 | R11: 2.25 | S11: 652230 | T11: 33.93911 | U11: 67.709953
A12: Afghanistan | B12: 2010 | C12: 1182.892 | D12: 7110.0001 | E12: 0.19 | F12: 0 | G12: 0.75 | H12: 79.78723 | I12: 8.27 | J12: 15.15 | K12: 60 | L12: 42.7 | M12: 20 | O12: 36500000 | P12: 14.362441 | Q12: 543.30653 | R12: 2.46 | S12: 652230 | T12: 33.93911 | U12: 67.709953
A13: Afghanistan | B13: 2011 | C13: 1436.1143 | D13: 8930.0003 | E13: 0.18 | F13: 0 | G13: 0.6 | H13: 76.92309 | I13: 8.13 | J13: 12.61 | K13: 60 | L13: 43.22202 | M13: 21.8 | O13: 28690000 | P13: 0.42635479 | Q13: 591.19003 | R13: 3.23 | S13: 652230 | T13: 33.93911 | U13: 67.709953
A14: Afghanistan | B14: 2012 | C14: 1324.1211 | D14: 8079.9999 | E14: 0.14 | F14: 0 | G14: 0.74 | H14: 84.09091 | I14: 9.29 | J14: 15.36 | K14: 60 | L14: 69.1 | M14: 23 | O14: 62630000 | P14: 12.752287 | Q14: 638.84585 | R14: 2.61 | S14: 652230 | T14: 33.93911 | U14: 67.709953
A15: Afghanistan | B15: 2013 | C15: 1060.7926 | D15: 5989.9998 | E15: 0.22 | F15: 0 | G15: 0.89 | H15: 80.180176 | I15: 9.1 | J15: 16.86 | K15: 60 | L15: 68.29065 | M15: 24.8 | O15: 268460000 | P15: 5.6007447 | Q15: 624.31545 | R15: 2.46 | S15: 652230 | T15: 33.93911 | U15: 67.709953
A16: Afghanistan | B16: 2014 | C16: 868.5762 | D16: 4880.0001 | E16: 0.16 | F16: 0 | G16: 1 | H16: 86.2069 | I16: 8.95 | J16: 18.93 | K16: 60 | L16: 89.5 | M16: 26.1 | O16: 6940000 | P16: 2.7245434 | Q16: 614.22334 | R16: 2.25 | S16: 652230 | T16: 33.93911 | U16: 67.709953
A17: Afghanistan | B17: 2015 | C17: 970.0803 | D17: 5949.9998 | E17: 0.15 | F17: 0 | G17: 1.03 | H17: 87.28814 | I17: 8.79 | J17: 17.53 | K17: 60 | L17: 71.5 | M17: 27.4 | O17: 4890000 | P17: 1.4513147 | Q17: 556.00722 | R17: 2.37 | S17: 652230 | T17: 33.93911 | U17: 67.709953
A18: Afghanistan | B18: 2016 | C18: 862.79114 | D18: 5300.0002 | E18: 0.15 | F18: 0 | G18: 1.06 | H18: 87.603294 | I18: 9.87 | J18: 19.92 | K18: 60 | L18: 97.7 | M18: 28.6 | O18: 860000 | P18: 2.2603142 | Q18: 512.01278 | R18: 2.24 | S18: 652230 | T18: 33.93911 | U18: 67.709953
... A21: Afghanistan | B21: 2019 | C21: 802.61255 | D21: 6079.9999 | E21: 0.18 | F21: 0 | G21: 0.89 | H21: 83.17757 | I21: 9.58 | J21: 18.51 | K21: 60 | L21: 97.7 | M21: 31.9 | O21: 4620000 | P21: 3.9116034 | Q21: 494.17935 | R21: 2.41 | S21: 652230 | T21: 33.93911 | U21: 67.709953
A22: Afghanistan | B22: 2020 | C22: 702.888 | E22: 0.12 | F22: 0 | G22: 0.68 | H22: 85 | I22: 9.35 | K22: 60 | L22: 97.7 | M22: 33.2 | P22: -2.3511007 | Q22: 516.74787 | S22: 652230 | T22: 33.93911 | U22: 67.709953
A23: Albania | B23: 2000 | C23: 9029.4375 | D23: 3170 | E23: 0.14 | F23: 0 | G23: 4.55 | H23: 97.01493 | K23: 105 | L23: 100 | M23: 38.2 | P23: 6.9462166 | Q23: 1126.6833 | R23: 4.13 | S23: 28748 | T23: 41.153332 | U23: 20.168331
A24: Albania | B24: 2001 | C24: 8635.532 | D24: 3230 | E24: 0.13 | F24: 0 | G24: 3.52 | H24: 96.438354 | K24: 105 | L24: 100 | M24: 40.5 | P24: 8.2933126 | Q24: 1281.6598 | R24: 3.89 | S24: 28748 | T24: 41.153332 | U24: 20.168331
A25: Albania | B25: 2002 | C25: 9443.555 | D25: 3760 | E25: 0.16 | F25: 0 | G25: 3.48 | H25: 95.60439 | K25: 105 | L25: 100 | M25: 43.2 | P25: 4.5365242 | Q25: 1425.1242 | R25: 4.1 | S25: 28748 | T25: 41.153332 | U25: 20.168331
A26: Albania | B26: 2003 | C26: 10756.612 | D26: 4070.0002 | E26: 0.1 | F26: 0 | G26: 5.12 | H26: 98.0843 | K26: 105 | L26: 100 | M26: 46.4 | P26: 5.5286375 | Q26: 1846.1201 | R26: 3.8 | S26: 28748 | T26: 41.153332 | U26: 20.168331
A27: Albania | B27: 2004 | C27: 11586.951 | D27: 4250 | E27: 0.13 | F27: 0 | G27: 5.41 | H27: 97.65343 | K27: 105 | L27: 100 | M27: 49 | P27: 5.5146679 | Q27: 2373.5813 | R27: 3.96 | S27: 28748 | T27: 41.153332 | U27: 20.168331
A28: Albania | B28: 2005 | C28: 11545.616 | D28: 4030.0002 | E28: 0.07 | F28: 0 | G28: 5.32 | H28: 98.7013 | K28: 105 | L28: 100 | M28: 51.9 | P28: 5.5264242 | Q28: 2673.7866 | R28: 3.75 | S28: 28748 | T28: 41.153332 | U28: 20.168331
A29: Albania | B29: 2006 | C29: 10976.728 | D29: 4010.0002 | E29: 0.09 | F29: 0 | G29: 4.95 | H29: 98.21428 | K29: 105 | L29: 100 | M29: 54.8 | P29: 5.902659 | Q29: 2972.7429 | R29: 3.46 | S29: 28748 | T29: 41.153332 | U29: 20.168331
A30: Albania | B30: 2007 | C30: 9534.874 | D30: 4139.9999 | E30: 0.07 | F30: 0 | G30: 2.76 | H30: 97.526505 | K30: 105 | L30: 100 | M30: 58.1 | P30: 5.9832595 | Q30: 3595.0381 | R30: 3.12 | S30: 28748 | T30: 41.153332 | U30: 20.168331
A31: Albania | B31: 2008 | C31: 10499.328 | D31: 4079.9999 | E31: 0.07 | F31: 0 | G31: 3.76 | H31: 98.172325 | K31: 105 | L31: 100 | M31: 60.8 | P31: 7.5000414 | Q31: 4370.5399 | R31: 3.01 | S31: 28748 | T31: 41.153332 | U31: 20.168331
A32: Albania | B32: 2009 | C32: 11524.428 | D32: 4219.9998 | E32: 0 | F32: 0 | G32: 5.2 | H32: 100 | K32: 105 | L32: 100 | M32: 63.6 | P32: 3.3542894 | Q32: 4114.1349 | R32: 2.98 | S32: 28748 | T32: 41.153332 | U32: 20.168331
A33: Albania | B33: 2010 | C33: 12377.504 | D33: 4449.9998 | E33: 0 | F33: 0 | G33: 7.49 | H33: 100 | K33: 105 | L33: 100 | M33: 66.5 | P33: 3.7069382 | Q33: 4094.3484 | R33: 2.85 | S33: 28748 | T33: 41.153332 | U33: 20.168331
A34: Albania | B34: 2011 | C34: 10854.649 | D34: 4849.9999 | E34: 0.06 | F34: 0 | G34: 4.09 | H34: 98.554214 | K34: 105 | L34: 100 | M34: 68.9 | P34: 2.5454061 | Q34: 4437.1426 | R34: 2.91 | S34: 28748 | T34: 41.153332 | U34: 20.168331
... A42: Albania | B42: 2019 | C42: 11585.555 | D42: 4829.9999 | E42: 0 | F42: 0 | G42: 5.17 | H42: 100 | K42: 105 | L42: 100 | M42: 80.7 | P42: 2.11342 | Q42: 5395.6595 | R42: 2.5 | S42: 28748 | T42: 41.153332 | U42: 20.168331
A43: Albania | B43: 2020 | C43: 11158.003 | E43: 0 | F43: 0 | G43: 5.31 | H43: 100 | K43: 105 | L43: 100 | M43: 81.3 | P43: -3.9553979 | Q43: 5246.2923 | S43: 28748 | T43: 41.153332 | U43: 20.168331
A44: Algeria | B44: 2000 | C44: 9746.524 | D44: 80050 | E44: 23.84 | F44: 0 | G44: 0.05 | H44: 0.20929259 | I44: 8.91 | J44: 0.43 | K44: 18 | L44: 98.9731 | M44: 97.1 | N44: 0.053235482 | P44: 3.8 | Q44: 1765.0271 | R44: 4.18 | S44: 2381741 | T44: 28.033886 | U44: 1.659626
A45: Algeria | B45: 2001 | C45: 9961.64 | D45: 78650 | E45: 24.96 | F45: 0 | G45: 0.07 | H45: 0.2796644 | I45: 8.79 | J45: 0.43 | K45: 18 | L45: 98.96687 | M45: 97.3 | N45: 0.065218486 | O45: 810000 | P45: 3 | Q45: 1740.6067 | R45: 4.07 | S45: 2381741 | T45: 28.033886 | U45: 1.659626
A46: Algeria | B46: 2002 | C46: 10180.35 | D46: 82400.002 | E46: 25.94 | F46: 0 | G46: 0.06 | H46: 0.23076923 | I46: 8.68 | J46: 0.51 | K46: 18 | L46: 98.95306 | M46: 97.8 | N46: 0.05167677 | O46: 310000 | P46: 5.6 | Q46: 1781.8289 | R46: 4.12 | S46: 2381741 | T46: 28.033886 | U46: 1.659626
A47: Algeria | B47: 2003 | C47: 10510.461 | D47: 88190.002 | E47: 27.54 | F47: 0 | G47: 0.26 | H47: 0.93525183 | I47: 8.57 | J47: 0.47 | K47: 18 | L47: 98.93401 | M47: 98 | N47: 0.228104 | O47: 90000 | P47: 7.2 | Q47: 2103.3813 | R47: 4.08 | S47: 2381741 | T47: 28.033886 | U47: 1.659626
A48: Algeria | B48: 2004 | C48: 10759.022 | D48: 89489.998 | E48: 29.14 | F48: 0 | G48: 0.25 | H48: 0.8506295 | I48: 8.46 | J48: 0.44 | K48: 18 | L48: 98.91208 | M48: 98.2 | N48: 0.2067869 | O48: 140000 | P48: 4.3 | Q48: 2610.1854 | R48: 3.96 | S48: 2381741 | T48: 28.033886 | U48: 1.659626
A49: Algeria | B49: 2005 | C49: 11113.723 | D49: 94190.002 | E49: 31.36 | F49: 0 | G49: 0.55 | H49: 1.7235976 | I49: 8.34 | J49: 0.58 | K49: 18 | L49: 98.88961 | M49: 98.5 | N49: 0.43411878 | O49: 160000 | P49: 5.9 | Q49: 3113.0949 | R49: 3.9 | S49: 2381741 | T49: 28.033886 | U49: 1.659626
...

Sheet imports
A1: Country Name | B1: Indicator Name | C1: 1988 | D1: 1989 | E1: 1990 | F1: 1991 | G1: 1992 | H1: 1993 | I1: 1994 | J1: 1995 | K1: 1996 | L1: 1997 | M1: 1998 | N1: 1999 | O1: 2000 | P1: 2001 | Q1: 2002 | R1: 2003 | S1: 2004 | T1: 2005 | U1: 2006 | V1: 2007 | W1: 2008 | X1: 2009 | Y1: 2010 | Z1: 2011 | AA1: 2012 | AB1: 2013 | AC1: 2014 | AD1: 2015 | AE1: 2016 | AF1: 2017 | AG1: 2018 | AH1: 2019 | AI1: 2020 | AJ1: 2021 | AK1: 2022
A2: Albania | B2: Energy imports, net (% of energy use) | E2: 6.4206002 | F2: -3.4848988 | G2: -3.3818124 | H2: 0.16870973 | I2: 3.5346718 | J2: 6.636723 | K2: 6.2928234 | L2: 8.699426 | M2: 16.285975 | N2: 42.023756 | O2: 46.518154 | P2: 53.182773 | Q2: 54.025411 | R2: 51.556771 | S2: 48.369835 | T2: 50.5736 | U2: 41.240008 | V2: 49.349867 | W2: 50.062006 | X2: 46.41059 | Y2: 28.962214 | Z2: 35.89477 | AA2: 15.717287 | AB2: 25.200423 | AC2: 28.911953 | AD2: 12.696462 | AE2: 20.272355 | AF2: 38.833601 | AG2: 21.269488 | AH2: 32.231803 | AI2: 36.469977 | AJ2: 24.117752 | AK2: 32.276397
A3: Algeria | B3: Energy imports, net (% of energy use) | E3: -348.57894 | F3: -334.6042 | G3: -331.51783 | H3: -331.86943 | I3: -330.51714 | J3: -338.1382 | K3: -377.43372 | L3: -403.68962 | M3: -407.93841 | N3: -411.8665 | O3: -425.82828 | P3: -406.35596 | Q3: -391.55749 | R3: -401.85756 | S3: -405.29567 | T3: -412.44299 | U3: -373.28933 | V3: -346.1207 | W3: -331.68217 | X3: -274.14298 | Y3: -268.12383 | Z3: -243.48577 | AA3: -209.6286 | AB3: -186.27162 | AC3: -171.45978 | AD3: -158.92568 | AE3: -178.80978 | AF3: -169.87922 | AG3: -152.18072 | AH3: -133.35275 | AI3: -124.74153 | AJ3: -137.10305 | AK3: -127.24359
A4: Angola | B4: Energy imports, net (% of energy use) | E4: -381.65006 | F4: -392.00095 | G4: -432.81887 | H4: -378.00752 | I4: -402.65416 | J4: -461.61801 | K4: -493.92883 | L4: -515.62022 | M4: -547.7561 | N4: -522.04701 | O4: -546.64497 | P4: -487.01426 | Q4: -575.45428 | R4: -520.18104 | S4: -590.35328 | T4: -812.88392 | U4: -818.58983 | V4: -905.05135 | W4: -910.83592 | X4: -775.82135 | Y4: -745.52456 | Z4: -646.02174 | AA4: -604.18323 | AB4: -608.40671 | AC4: -637.73029 | AD4: -568.891 | AE4: -599.54334 | AF4: -564.38488 | AG4: -558.35077 | AH4: -488.93284 | AI4: -474.84656 | AJ4: -373.79663 | AK4: -353.97182
A5: Argentina | B5: Energy imports, net (% of energy use) | E5: -4.0712593 | F5: -3.8545467 | G5: -7.142339 | H5: -10.783483 | I5: -16.997101 | J5: -23.342176 | K5: -28.306974 | L5: -31.273288 | M5: -30.198901 | N5: -30.411482 | O5: -33.842833 | P5: -44.462606 | Q5: -44.631023 | R5: -40.163476 | S5: -28.031842 | T5: -24.036959 | U5: -18.716217 | V5: -8.758409 | W5: -6.2618363 | X5: -7.6558715 | Y5: -2.4021676 | Z5: 7.2374168 | AA5: 8.1143991 | AB5: 13.986218 | AC5: 14.06781 | AD5: 13.547781 | AE5: 11.999369 | AF5: 13.218915 | AG5: 8.6087553 | AH5: 2.4916771 | AI5: 1.2280062 | AJ5: 5.9663681 | AK5: 1.9585582
A6: Armenia | B6: Energy imports, net (% of energy use) | E6: 100.6559 | G6: 97.039692 | L6: 71.485743 | M6: 71.645005 | N6: 65.308063 | O6: 71.191142 | P6: 72.565339 | Q6: 62.98479 | R6: 65.869859 | S6: 65.686174 | T6: 67.237036 | U6: 68.024792 | V6: 72.809235 | W6: 75.140116 | X6: 69.25625 | Y6: 69.640109 | Z6: 69.018011 | AA6: 74.340381 | AB6: 73.68226 | AC6: 71.659229 | AD6: 67.629316 | AE6: 68.24481 | AF6: 68.960568 | AG6: 72.731774 | AH6: 74.170785 | AI6: 74.147267 | AJ6: 78.904516 | AK6: 76.872109
A7: Australia | B7: Energy imports, net (% of energy use) | E7: -74.903416 | F7: -93.637584 | G7: -95.915183 | H7: -92.366025 | I7: -91.374285 | J7: -96.451627 | K7: -91.090923 | L7: -100.7275 | M7: -107.39021 | N7: -103.45437 | O7: -117.60269 | P7: -126.51362 | Q7: -130.62417 | R7: -125.2887 | S7: -125.87203 | T7: -131.07467 | U7: -123.80691 | V7: -127.76429 | W7: -123.53461 | X7: -128.47662 | Y7: -146.70835 | Z7: -141.94293 | AA7: -149.19538 | AB7: -164.69177 | AC7: -185.55579 | AD7: -197.38684 | AE7: -206.23025 | AF7: -213.03922 | AG7: -221.13515 | AH7: -230.54025 | AI7: -237.32858 | AJ7: -232.10477 | AK7: -234.27935
A8: Austria | B8: Energy imports, net (% of energy use) | E8: 69.792467 | F8: 67.896537 | G8: 69.796048 | H8: 67.025531 | I8: 66.447964 | J8: 67.688588 | K8: 70.855776 | L8: 68.783292 | M8: 71.665228 | N8: 66.633473 | O8: 66.900318 | P8: 66.272663 | Q8: 69.180972 | R8: 72.072861 | S8: 72.736024 | T8: 73.395954 | U8: 73.793048 | V8: 70.172563 | W8: 70.477076 | X8: 66.710388 | Y8: 64.315577 | Z8: 71.892759 | AA8: 65.520586 | AB8: 62.883565 | AC8: 67.488882 | AD8: 62.147421 | AE8: 64.113786 | AF8: 65.946381 | AG8: 66.525778 | AH8: 74.476282 | AI8: 59.766877 | AJ8: 53.15293 | AK8: 76.811185
A9: Azerbaijan | B9: Energy imports, net (% of energy use) | E9: 12.230552 | F9: 16.273306 | G9: 3.9842959 | H9: -1.7221529 | I9: 1.8865854 | J9: -15.161915 | K9: -21.134066 | L9: -23.142724 | M9: -33.571436 | N9: -72.323465 | O9: -65.862621 | P9: -68.858086 | Q9: -71.888583 | R9: -61.706348 | S9: -55.178726 | T9: -93.951693 | U9: -182.88923 | V9: -323.14755 | W9: -326.67337 | X9: -425.32075 | Y9: -457.06933 | Z9: -377.9802 | AA9: -326.99964 | AB9: -326.52807 | AC9: -312.69973 | AD9: -311.3727 | AE9: -307.15744 | AF9: -278.23586 | AG9: -286.42024 | AH9: -274.41746 | AI9: -274.46061 | AJ9: -287.01653 | AK9: -263.12754
A10: Bahrain | B10: Energy imports, net (% of energy use) | E10: -154.67004 | F10: -156.1239 | G10: -143.14576 | H10: -143.38118 | I10: -125.45981 | J10: -129.20065 | K10: -126.63248 | L10: -118.84261 | M10: -114.74377 | N10: -106.17925 | O10: -97.825586 | P10: -97.38321 | Q10: -94.195608 | R10: -88.231432 | S10: -80.534361 | T10: -60.627317 | U10: -60.115304 | V10: -53.528028 | W10: -45.866588 | X10: -54.728337 | Y10: -53.407057 | Z10: -58.314694 | AA10: -56.775094 | AB10: -54.383116 | AC10: -65.71838 | AD10: -57.361738 | AE10: -57.29019 | AF10: -56.80998 | AG10: -53.600543 | AH10: -53.430627 | AI10: -51.90139 | AJ10: -50.226333 | AK10: -45.475132
A11: Bangladesh | B11: Energy imports, net (% of energy use) | E11: 16.925278 | F11: 14.56751 | G11: 14.098282 | H11: 13.953878 | I11: 15.285043 | O11: 17.650915 | P11: 21.103895 | Q11: 19.70622 | R11: 19.928574 | S11: 17.792065 | T11: 17.909554 | U11: 16.110349 | V11: 15.829946 | W11: 15.494329 | X11: 14.740472 | Y11: 14.454455 | Z11: 17.464638 | AA11: 18.355917 | AB11: 17.964054 | AC11: 19.628963 | AD11: 20.400209 | AE11: 21.671916 | AF11: 23.88997 | AG11: 24.574116 | AH11: 30.297494 | AI11: 34.46204 | AJ11: 39.590069 | AK11: 44.307026
A12: Belarus | B12: Energy imports, net (% of energy use) | E12: 92.709262 | F12: 90.300896 | G12: 88.688387 | H12: 87.921985 | I12: 84.807997 | J12: 87.147907 | K12: 83.381678 | L12: 88.348126 | M12: 86.196477 | N12: 84.290058 | O12: 85.491586 | P12: 84.922212 | Q12: 84.340551 | R12: 85.235838 | S12: 86.594078 | T12: 85.396022 | U12: 86.224521 | V12: 84.71559 | W12: 87.750868 | X12: 83.534171 | Y12: 84.979709 | Z12: 84.146163 | AA12: 87.246613 | AB12: 86.726893 | AC12: 87.767382 | AD12: 84.959928 | AE12: 83.313868 | AF12: 84.894044 | AG12: 86.028155 | AH12: 85.255535 | AI12: 83.841231 | AJ12: 78.289958 | AK12: 77.079948
A13: Belgium | B13: Energy imports, net (% of energy use) | E13: 83.036796 | F13: 84.764993 | G13: 85.761616 | H13: 84.53652 | I13: 87.120842 | J13: 88.086939 | K13: 88.322853 | L13: 86.887808 | M13: 90.173114 | N13: 85.069962 | O13: 87.21996 | P13: 89.760923 | Q13: 88.5769 | R13: 91.440452 | S13: 91.768603 | T13: 91.873267 | U13: 92.466114 | V13: 91.142835 | W13: 95.950877 | X13: 86.602839 | Y13: 89.345984 | Z13: 86.778353 | AA13: 86.342803 | AB13: 87.315604 | AC13: 89.705861 | AD13: 95.272255 | AE13: 86.254228 | AF13: 86.938044 | AG13: 99.699001 | AH13: 90.930226 | AI13: 89.07581 | AJ13: 81.496156 | AK13: 86.761944
A14: Benin | B14: Energy imports, net (% of energy use) | E14: -5.5370285 | F14: -5.9790457 | G14: -2.1444461 | H14: -2.7405027 | I14: -1.2102954 | J14: 0.95287349 | K14: 11.500838 | L14: 16.260528 | M14: 16.957243 | N14: 23.283169 | O14: 28.09771 | P14: 29.872469 | Q14: 31.955106 | R14: 34.470607 | S14: 35.089418 | T14: 35.847037 | U14: 39.107901 | V14: 41.801795 | W14: 42.256518 | X14: 44.71661 | Y14: 49.305667 | AH14: 46.041641 | AI14: 46.633622 | AJ14: 42.756759 | AK14: 40.90317
A15: Bolivia | B15: Energy imports, net (% of energy use) | E15: -91.590738 | F15: -90.818104 | G15: -80.389417 | H15: -72.950996 | I15: -69.005949 | J15: -55.167434 | K15: -42.702088 | L15: -27.678749 | M15: -26.188833 | N15: -18.291124 | O15: -49.65056 | P15: -82.38244 | Q15: -73.490177 | R15: -94.16115 | S15: -145.62147 | T15: -163.59353 | U15: -171.32397 | V15: -180.91141 | W15: -183.61036 | X15: -136.60464 | Y15: -148.35164 | Z15: -148.43925 | AA15: -160.63805 | AB15: -191.99225 | AC15: -179.20045 | AD15: -174.58382 | AE15: -149.60013 | AF15: -132.55609 | AG15: -114.95634 | AH15: -90.754165 | AI15: -119.86122 | AJ15: -95.167052 | AK15: -67.333905
A16: Bosnia and Herzegovina | B16: Energy imports, net (% of energy use) | F16: 31.900268 | G16: 18.497979 | H16: 16.435434 | I16: 49.749513 | J16: 47.875571 | K16: 38.67798 | L16: 21.845775 | M16: 24.300499 | N16: 22.353238 | O16: 29.020877 | P16: 27.590972 | Q16: 24.696444 | R16: 21.053003 | S16: 25.547924 | T16: 27.468663 | U16: 26.357676 | V16: 30.647442 | W16: 29.036342 | X16: 30.577303 | Y16: 31.196082 | Z16: 33.994826 | AA16: 33.294503 | AB16: 29.722408 | AC16: 28.212705 | AD16: 33.708899 | AE16: 31.559987 | AF16: 34.076435 | AG16: 24.281114 | AH16: 27.394097 | AI16: 25.393447 | AJ16: 27.180586 | AK16: 26.368061
A17: Botswana | B17: Energy imports, net (% of energy use) | Y17: 47.927469 | Z17: 50.519594 | AA17: 46.854629 | AB17: 45.521193 | AC17: 37.335962 | AD17: 34.929685 | AE17: 36.345923 | AF17: 31.89868 | AG17: 30.949012 | AH17: 33.186239 | AI17: 30.85959 | AJ17: 30.181619 | AK17: 23.681778
A18: Brazil | B18: Energy imports, net (% of energy use) | E18: 27.922391 | F18: 27.826399 | G18: 27.48925 | H18: 30.851937 | I18: 30.023153 | J18: 29.918804 | K18: 32.020564 | L18: 31.060068 | M18: 28.442663 | N18: 25.482916 | O18: 23.641203 | P18: 21.066972 | Q18: 15.693066 | R18: 12.650434 | S18: 14.987125 | T18: 11.709392 | U18: 9.4248744 | V18: 10.755451 | W18: 10.973437 | X18: 6.602297 | Y18: 9.4605638 | Z18: 10.701608 | AA18: 12.135917 | AB18: 15.779929 | AC18: 14.224612 | AD18: 8.6138733 | AE18: 2.673007 | AF18: 1.1405856 | AG18: -0.81675403 | AH18: -4.0596361 | AI18: -11.167735 | AJ18: -3.8476311 | AK18: -7.2872105
A19: Brunei | B19: Energy imports, net (% of energy use) | E19: -799.8963 | F19: -737.47539 | G19: -725.03184 | H19: -746.85577 | I19: -830.26395 | J19: -703.38572 | K19: -679.12633 | L19: -635.27578 | M19: -628.17299 | N19: -674.54696 | O19: -725.65394 | P19: -790.40928 | Q19: -833.77756 | R19: -739.14337 | S19: -793.86989 | T19: -839.54522 | U19: -604.86445 | V19: -539.09714 | W19: -488.91667 | X19: -511.8917 | Y19: -472.22804 | Z19: -376.26828 | AA19: -378.75655 | AB19: -453.06912 | AC19: -351.38075 | AD19: -486.23581 | AE19: -405.09178 | AF19: -332.16902 | AG19: -339.57889 | AH19: -266.99692 | AI19: -245.56382 | AJ19: -228.68023 | AK19: -172.55263
A20: Bulgaria | B20: Energy imports, net (% of energy use) | E20: 64.13341 | F20: 64.527991 | G20: 58.002256 | H20: 60.340227 | I20: 56.82267 | J20: 58.775071 | K20: 57.43798 | L20: 51.7156 | M20: 50.531982 | N20: 48.712723 | O20: 46.864953 | P20: 46.675433 | Q20: 47.421179 | R20: 47.428643 | S20: 49.060099 | T20: 48.080079 | U20: 46.864859 | V20: 51.989495 | W20: 53.004979 | X20: 46.382605 | Y20: 40.85265 | Z20: 37.237482 | AA20: 37.354017 | AB20: 39.053926 | AC20: 35.715193 | AD20: 37.131814 | AE20: 39.329357 | AF20: 40.266772 | AG20: 37.371503 | AH20: 39.323183 | AI20: 38.921745 | AJ20: 36.895349 | AK20: 37.962661
A21: Cambodia | B21: Energy imports, net (% of energy use) | AI21: 60.586801 | AJ21: 58.931308
A22: Cameroon | B22: Energy imports, net (% of energy use) | E22: -122.14732 | F22: -114.05853 | G22: -112.07999 | H22: -97.988223 | I22: -89.597448 | J22: -76.607857 | K22: -77.330023 | L22: -82.912802 | M22: -86.7051 | N22: -80.50566 | O22: -75.231121 | P22: -65.993056 | Q22: -65.53435 | R22: -57.267994 | S22: -51.692941 | T22: -48.45375 | U22: -51.024657 | V22: -48.753263 | W22: -48.308925 | X22: -31.552409 | Y22: -23.200884 | Z22: -13.258851 | AA22: -15.07492 | AB22: -18.262819 | AC22: -19.664629 | AD22: -27.961788 | AE22: -27.952799 | AF22: -20.564834 | AG22: -24.050145 | AH22: -31.903384 | AI22: -31.243405 | AJ22: -29.7632 | AK22: -28.712684
A23: Canada | B23: Energy imports, net (% of energy use) | E23: -28.035109 | F23: -36.179583 | G23: -38.80463 | H23: -42.052583 | I23: -46.185203 | J23: -51.081815 | K23: -50.428065 | L23: -50.463863 | M23: -52.138068 | N23: -49.873936 | O23: -50.589519 | P23: -51.790605 | Q23: -54.762452 | R23: -49.269134 | S23: -50.389794 | T23: -47.977101 | U23: -50.428761 | V23: -54.590049 | W23: -52.792558 | X23: -52.91117 | Y23: -55.142238 | Z23: -56.292996 | AA23: -59.752255 | AB23: -65.704813 | AC23: -66.696675 | AD23: -68.422156 | AE23: -69.117305 | AF23: -71.731473 | AG23: -75.0034 | AH23: -75.769176 | AI23: -79.703982 | AJ23: -87.582136 | AK23: -89.488095
A24: Chad | B24: Energy imports, net (% of energy use) | O24: 3.1943428 | P24: 3.7381818 | Q24: 4.5200881 | R24: -72.142562 | S24: -378.63452 | T24: -370.79361 | U24: -325.09212 | V24: -290.73118 | W24: -248.33325 | X24: -217.45833 | Y24: -225.61288 | Z24: -183.96186 | AA24: -117.29275 | AB24: -132.26487 | AF24: -157.66185 | AG24: -171.72708 | AH24: -204.99154 | AI24: -203.00917 | AJ24: -176.63058 | AK24: -177.76264
A25: Chile | B25: Energy imports, net (% of energy use) | E25: 50.14542 | F25: 50.646308 | G25: 49.546873 | H25: 51.089244 | I25: 58.342137 | J25: 59.085298 | K25: 64.169372 | L25: 64.643817 | M25: 69.505481 | N25: 71.281617 | O25: 70.494045 | P25: 67.836546 | Q25: 69.084038 | R25: 71.333772 | S25: 75.29682 | T25: 72.246247 | U25: 72.933961 | V25: 77.91174 | W25: 72.750094 | X25: 70.243593 | Y25: 72.270444 | Z25: 73.831174 | AA25: 67.13843 | AB25: 65.871558 | AC25: 67.250829 | AD25: 68.18478 | AE25: 69.176897 | AF25: 68.361002 | AG25: 67.663563 | AH25: 69.225887 | AI25: 66.718239 | AJ25: 68.863243 | AK25: 66.273212
A26: China | B26: Energy imports, net (% of energy use) | E26: -3.9913418 | F26: -3.5844946 | G26: -2.6338217 | H26: -0.36876894 | I26: -1.470725 | J26: -1.2456799 | K26: -1.12647 | L26: 0.64973803 | M26: 0.30562276 | N26: 1.2667492 | O26: 2.4580751 | P26: 0.095412582 | Q26: 1.5507739 | R26: 2.8178772 | S26: 5.8057075 | T26: 5.6086158 | U26: 6.9593964 | V26: 7.9460986 | W26: 8.6324519 | X26: 12.07848 | Y26: 13.58229 | Z26: 14.718738 | AA26: 16.551908 | AB26: 17.326032 | AC26: 17.541175 | AD26: 16.706423 | AE26: 19.193074 | AF26: 20.41899 | AG26: 21.668746 | AH26: 22.220974 | AI26: 22.974572 | AJ26: 21.638661 | AK26: 20.624559
A27: Colombia | B27: Energy imports, net (% of energy use) | E27: -89.274856 | F27: -92.329935 | G27: -80.862866 | H27: -88.923178 | I27: -86.105094 | J27: -106.73597 | K27: -125.49443 | L27: -139.27358 | M27: -157.17439 | N27: -195.40334 | O27: -183.11663 | P27: -176.85945 | Q27: -171.42119 | R27: -181.33368 | S27: -192.72764 | T27: -189.66106 | U27: -198.79933 | V27: -202.67752 | W27: -206.85479 | X27: -216.44726 | Y27: -245.91526 | Z27: -284.1845 | AA27: -308.77157 | AB27: -223.80397 | AC27: -237.43279 | AD27: -212.7697 | AE27: -201.1411 | AF27: -250.10761 | AG27: -228.7851 | AH27: -181.41411 | AI27: -192.84562 | AJ27: -145.26017 | AK27: -139.1242
A28: Congo, Rep. | B28: Energy imports, net (% of energy use) | E28: -1002.1235 | F28: -944.82859 | G28: -1056.0656 | H28: -1153.3976 | I28: -1251.6419 | J28: -1148.277 | K28: -1364.9899 | L28: -1633.8764 | M28: -1777.6506 | N28: -1939.3452 | O28: -1931.3293 | P28: -1590.599 | Q28: -1524.6611 | R28: -1166.2476 | S28: -1135.5995 | T28: -1152.2313 | U28: -998.36698 | V28: -892.29106 | W28: -875.81705 | X28: -922.44264 | Y28: -934.27953 | Z28: -632.16269 | AA28: -537.70637 | AB28: -453.8497 | AC28: -459.95644 | AD28: -420.1744 | AE28: -395.35511 | AF28: -463.76083 | AG28: -548.5007 | AH28: -511.22993 | AI28: -452.50849 | AJ28: -391.39312 | AK28: -347.41987
A29: Costa Rica | B29: Energy imports, net (% of energy use) | E29: 62.001339 | F29: 60.44692 | G29: 62.720461 | H29: 63.856183 | I29: 66.885487 | J29: 69.97913 | K29: 66.807884 | L29: 64.959257 | M29: 72.538273 | N29: 71.233487 | O29: 61.418134 | P29: 65.252158 | Q29: 64.244491 | R29: 62.669801 | S29: 52.036171 | T29: 54.956833 | U29: 54.481972 | V29: 56.272567 | W29: 57.266885 | X29: 51.888476 | Y29: 53.24357 | Z29: 54.348382 | AA29: 50.292124 | AB29: 51.041448 | AC29: 52.250373 | AD29: 50.898603 | AE29: 56.106193 | AF29: 60.518741 | AG29: 58.366919 | AH29: 57.963811 | AI29: 46.820616 | AJ29: 53.383697 | AK29: 53.080233
A30: Cote d'Ivoire | B30: Energy imports, net (% of energy use) | E30: 25.079007 | F30: 26.590766 | G30: 26.186826 | H30: 25.63444 | I30: 25.420654 | J30: 20.892431 | K30: 14.080341 | L30: 11.050065 | M30: 11.343933 | N30: 17.076744 | O30: 14.60034 | P30: 11.590095 | Q30: 9.2432547 | R30: -0.0079621004 | S30: -1.7069851 | T30: -7.292621 | U30: -24.056513 | V30: -12.821686 | W30: -13.484114 | X30: -15.865259 | Y30: -10.283548 | Z30: -6.364434 | AA30: 1.6296279 | AB30: 6.0660659 | AC30: 7.7174236 | AD30: 3.2078959 | AE30: 5.1000774 | AF30: 3.0147243 | AG30: 7.7921101 | AH30: 4.6010464 | AI30: 8.1437856 | AJ30: 13.230067 | AK30: 14.378609
A31: Croatia | B31: Energy imports, net (% of energy use) | E31: 40.955874 | F31: 30.903326 | G31: 36.135952 | H31: 34.033681 | I31: 37.598812 | J31: 35.985978 | K31: 41.468946 | L31: 43.851041 | M31: 46.645048 | N31: 49.547662 | O31: 48.890391 | P31: 47.11787 | Q31: 54.98708 | R31: 51.169738 | S31: 52.436006 | T31: 53.256358 | U31: 49.779714 | V31: 52.477298 | W31: 55.536239 | X31: 46.635024 | Y31: 47.349206 | Z31: 50.458577 | AA31: 50.63929 | AB31: 48.282439 | AC31: 45.019109 | AD31: 49.628925 | AE31: 49.307656 | AF31: 54.257563 | AG31: 54.123044 | AH31: 57.796268 | AI31: 54.170846 | AJ31: 55.430659 | AK31: 61.895536
A32: Cuba | B32: Energy imports, net (% of energy use) | U32: 49.792369 | V32: 47.918472 | W32: 51.244614 | X32: 55.537394 | Y32: 61.504332 | Z32: 57.410361 | AA32: 58.170102 | AB32: 56.995896 | AC32: 54.186043 | AD32: 54.839625 | AE32: 58.750618 | AF32: 55.238831 | AG32: 50.393946 | AH32: 52.813625 | AI32: 53.593771 | AJ32: 58.13848 | AK32: 62.813333
A33: Curaçao | B33: Energy imports, net (% of energy use) | E33: 215.07558 | F33: 201.40377 | G33: 247.42082 | H33: 247.70628 | I33: 241.35279 | J33: 240.64476 | K33: 237.60666 | L33: 176.2832 | M33: 169.1865 | N33: 196.1447 | O33: 197.30385 | P33: 193.54825 | Q33: 195.54145 | R33: 200.50584 | S33: 195.84743 | T33: 200.96229 | U33: 204.84639 | V33: 194.83952 | W33: 201.40061 | X33: 196.99188 | Y33: 210.1385 | Z33: 201.88631 | AA33: 199.02366 | AB33: 203.85045 | AC33: 192.12151 | AD33: 190.39331 | AE33: 204.73102 | AF33: 223.77125 | AG33: 236.119
A34: Cyprus | B34: Energy imports, net (% of energy use) | K34: 116.39848 | AD34: 120.80098 | AE34: 120.81703 | AJ34: 108.44315 | AK34: 117.03786
A35: Czech Republic | B35: Energy imports, net (% of energy use) | E35: 15.286446 | F35: 15.710724 | G35: 15.792553 | H35: 15.916368 | I35: 18.753968 | J35: 20.551217 | K35: 24.226558 | L35: 24.106357 | M35: 25.114363 | N35: 25.081737 | O35: 22.779863 | P35: 25.1361 | Q35: 26.335945 | R35: 25.062337 | S35: 25.557503 | T35: 28.10374 | U35: 27.666134 | V35: 25.130086 | W35: 27.930635 | X35: 27.000781 | Y35: 25.554911 | Z35: 28.884721 | AA35: 25.429576 | AB35: 27.710578 | AC35: 30.286925 | AD35: 32.117295 | AE35: 32.877933 | AF35: 37.288014 | AG35: 37.08666 | AH35: 41.0173 | AI35: 38.784971 | AJ35: 40.026141 | AK35: 42.023364
A36: Denmark | B36: Energy imports, net (% of energy use) | E36: 49.818731 | F36: 42.751863 | G36: 40.187632 | H36: 30.103981 | I36: 30.248665 | J36: 37.479657 | K36: 24.269617 | L36: 17.402778 | M36: 6.1702938 | N36: -18.762203 | O36: -40.050456 | P36: -31.520106 | Q36: -45.964934 | R36: -34.238571 | S36: -51.115235 | T36: -55.216611 | U36: -38.957808 | V36: -26.75326 | W36: -23.265115 | X36: -20.242147 | Y36: -17.632651 | Z36: -6.9301774 | AA36: -3.4730256 | AB36: 13.334643 | AC36: 13.460392 | AD36: 14.41915 | AE36: 14.973743 | AF36: 12.471322 | AG36: 25.164627 | AH36: 43.767617 | AI36: 48.334348 | AJ36: 34.830756 | AK36: 47.39572
A37: Dominican Republic | B37: Energy imports, net (% of energy use) | AA37: 93.229324 | AB37: 93.032548 | AC37: 93.565312 | AD37: 95.356582 | AE37: 94.424446 | AF37: 93.040809 | AG37: 93.420206 | AH37: 93.940654 | AI37: 89.586616 | AJ37: 91.28738 | AK37: 94.420689
A38: Ecuador | B38: Energy imports, net (% of energy use) | E38: -159.27593 | F38: -156.93454 | G38: -178.5753 | H38: -199.70294 | I38: -200.15316 | J38: -177.25404 | K38: -160.39118 | L38: -144.82279 | M38: -137.87269 | N38: -157.39994 | O38: -169.13479 | P38: -155.41631 | Q38: -131.04701 | R38: -123.53776 | S38: -168.17067 | T38: -149.12926 | U38: -153.09402 | V38: -129.46671 | W38: -150.58346 | X38: -118.84378 | Y38: -106.15226 | Z38: -104.75 | AA38: -108.89053 | AB38: -105.56654 | AC38: -98.818671 | AD38: -101.68852 | AE38: -113.6296 | AF38: -104.55086 | AG38: -98.711527 | AH38: -95.754232 | AI38: -105.89822 | AJ38: -75.60515 | AK38: -69.401315
A39: Egypt, Arab Rep. | B39: Energy imports, net (% of energy use) | E39: -61.760888 | F39: -61.844372 | G39: -66.239941 | H39: -65.836086 | I39: -67.704471 | J39: -60.061574 | K39: -46.313477 | L39: -38.201695 | M39: -30.310218 | N39: -31.280713 | O39: -23.171586 | P39: -17.838431 | Q39: -19.274931 | R39: -19.317782 | S39: -11.464638 | T39: -22.487342 | U39: -20.936627 | V39: -19.33036 | W39: -21.079934 | X39: -16.965407 | Y39: -15.282542 | Z39: -9.0916768 | AA39: -3.823938 | AB39: 0.75107387 | AC39: 8.0901448 | AD39: 12.861115 | AE39: 19.05399 | AF39: 14.129952 | AG39: 4.9957346 | AH39: -0.53103398 | AI39: -0.068294372 | AJ39: 1.6352104 | AK39: 9.7851068
A40: El Salvador | B40: Energy imports, net (% of energy use) | E40: 32.053477 | F40: 37.633188 | G40: 39.75994 | H40: 44.605665 | I40: 44.179066 | J40: 49.276846 | K40: 45.558366 | L40: 48.698655 | M40: 51.401857 | N40: 48.462919 | O40: 59.872955 | P40: 56.654078 | Q40: 55.983588 | R40: 57.517017 | S40: 57.277763 | T40: 54.229667 | U40: 53.502166 | V40: 56.263197 | W40: 50.574499 | X40: 50.965735 | Y40: 49.375187 | Z40: 49.69928 | AA40: 49.569779 | AB40: 52.717821 | AC40: 56.10994 | AD40: 58.398868 | AE40: 58.376272 | AF40: 54.946927 | AG40: 57.451914 | AH40: 61.322795 | AI40: 51.479107 | AJ40: 56.933114 | AK40: 59.505445
...

Sheet glued
A1: Entity | B1: Year | C1: Primary energy consumption per capita (kWh/person) | D1: Value_co2_emissions_kt_by_country | E1: Electricity from fossil fuels (TWh) | F1: Electricity from renewables (TWh) | G1: Low-carbon electricity (% electricity) | H1: Density\n(P/Km2) | I1: Access to electricity (% of population) | J1: Renewables (% equivalent primary energy) | K1: gdp_growth | L1: gdp_per_capita | M1: Land Area(Km2) | N1: Latitude | O1: Longitude | P1: Energy imports, net (% of energy use)
A2: Afghanistan | B2: 2019 | C2: 802.61255 | D2: 6079.9999 | E2: 0.18 | F2: 0.89 | G2: 83.17757 | H2: 60 | I2: 97.7 | K2: 3.9116034 | L2: 494.17935 | M2: 652230 | N2: 33.93911 | O2: 67.709953 | P2: =VLOOKUP(A2, imports_filtered!$A$2:$C$1000, 2, 0) -> #N/A
A3: Albania | B3: 2019 | C3: 11585.555 | D3: 4829.9999 | E3: 0 | F3: 5.17 | G3: 100 | H3: 105 | I3: 100 | K3: 2.11342 | L3: 5395.6595 | M3: 28748 | N3: 41.153332 | O3: 20.168331 | P3: =VLOOKUP(A3, imports_filtered!$A$2:$C$1000, 2, 0) -> 32.231803
A4: Algeria | B4: 2019 | C4: 16259.053 | D4: 171250 | E4: 75.85 | F4: 0.84 | G4: 1.0953188 | H4: 18 | I4: 99.5 | J4: 0.29474697 | K4: 1 | L4: 3989.6683 | M4: 2381741 | N4: 28.033886 | O4: 1.659626 | P4: =VLOOKUP(A4, imports_filtered!$A$2:$C$1000, 2, 0) -> -133.35275
A5: Angola | B5: 2019 | C5: 3667.4238 | D5: 25209.999 | E5: 4.38 | F5: 11.02 | G5: 71.55844 | H5: 26 | I5: 45.6428 | K5: -0.62464432 | L5: 2809.6261 | M5: 1246700 | N5: -11.202692 | O5: 17.873887 | P5: =VLOOKUP(A5, imports_filtered!$A$2:$C$1000, 2, 0) -> -488.93284
A6: Antigua and Barbuda | B6: 2019 | C6: 33027.516 | D6: 519.99998 | E6: 0.33 | F6: 0.01 | G6: 2.9411764 | H6: 223 | I6: 100 | K6: 4.8622362 | L6: 17376.65 | M6: 443 | N6: 17.060816 | O6: -61.796428 | P6: =VLOOKUP(A6, imports_filtered!$A$2:$C$1000, 2, 0) -> #N/A
A7: Argentina | B7: 2019 | C7: 20725.168 | D7: 168100.01 | E7: 90.56 | F7: 34.63 | G7: 31.991589 | H7: 17 | I7: 100 | J7: 11.926772 | K7: -2.0259342 | L7: 10056.638 | M7: 2780400 | N7: -38.416097 | O7: -63.616672 | P7: =VLOOKUP(A7, imports_filtered!$A$2:$C$1000, 2, 0) -> 2.4916771
A8: Armenia | B8: 2019 | C8: 16179.096 | D8: 6170.0001 | E8: 2.86 | F8: 2.41 | G8: 60.821915 | H8: 104 | I8: 100 | K8: 7.6 | L8: 4604.6463 | M8: 29743 | N8: 40.069099 | O8: 45.038189 | P8: =VLOOKUP(A8, imports_filtered!$A$2:$C$1000, 2, 0) -> 74.170785
A9: Aruba | B9: 2019 | C9: 51107.844 | E9: 0.77 | F9: 0.15 | G9: 16.304348 | H9: 590 | I9: 100 | M9: 179 | N9: 12.52111 | O9: -69.96833 | P9: =VLOOKUP(A9, imports_filtered!$A$2:$C$1000, 2, 0) -> #N/A
A10: Australia | B10: 2019 | C10: 66263.54 | D10: 386530 | E10: 196.45 | F10: 53.41 | G10: 21.37597 | H10: 3 | I10: 100 | J10: 8.880722 | K10: 2.1131494 | L10: 54875.286 | M10: 7741220 | N10: -25.274398 | O10: 133.77514 | P10: =VLOOKUP(A10, imports_filtered!$A$2:$C$1000, 2, 0) -> -230.54025
A11: Austria | B11: 2019 | C11: 48314.258 | D11: 64769.997 | E11: 16.22 | F11: 54.64 | G11: 77.109795 | H11: 109 | I11: 100 | J11: 35.611378 | K11: 1.4912109 | L11: 50114.401 | M11: 83871 | N11: 47.516231 | O11: 14.550072 | P11: =VLOOKUP(A11, imports_filtered!$A$2:$C$1000, 2, 0) -> 74.476282
A12: Azerbaijan | B12: 2019 | C12: 17546.781 | D12: 35509.998 | E12: 22.91 | F12: 1.69 | G12: 6.869919 | H12: 123 | I12: 100 | J12: 2.674584 | K12: 2.5 | L12: 4805.7537 | M12: 86600 | N12: 40.143105 | O12: 47.576927 | P12: =VLOOKUP(A12, imports_filtered!$A$2:$C$1000, 2, 0) -> -274.41746
A13: Bahamas | B13: 2019 | C13: 39636.066 | E13: 2.1 | F13: 0 | G13: 0 | H13: 41 | I13: 100 | M13: 13878 | N13: 25.025885 | O13: -78.035889 | P13: =VLOOKUP(A13, imports_filtered!$A$2:$C$1000, 2, 0) -> #N/A
A14: Bahrain | B14: 2019 | C14: 155398.47 | D14: 33259.998 | E14: 31.43 | F14: 0.01 | G14: 0.031806614 | H14: 2239 | I14: 100 | K14: 2.1413768 | L14: 23551.93 | M14: 765 | N14: 26.0667 | O14: 50.5577 | P14: =VLOOKUP(A14, imports_filtered!$A$2:$C$1000, 2, 0) -> -53.430627
A15: Bangladesh | B15: 2019 | C15: 2916.3176 | D15: 90739.998 | E15: 78.37 | F15: 1.14 | G15: 1.4337819 | H15: 1265 | I15: 92.2 | J15: 0.6751287 | K15: 8.1526841 | L15: 1855.7401 | M15: 148460 | N15: 23.684994 | O15: 90.356331 | P15: =VLOOKUP(A15, imports_filtered!$A$2:$C$1000, 2, 0) -> 30.297494
A16: Barbados | B16: 2019 | C16: 25172.027 | D16: 1250 | E16: 0.98 | F16: 0.04 | G16: 3.9215686 | H16: 668 | I16: 100 | K16: -0.096135553 | L16: 18148.498 | M16: 430 | N16: 13.193887 | O16: -59.543198 | P16: =VLOOKUP(A16, imports_filtered!$A$2:$C$1000, 2, 0) -> #N/A
A17: Belarus | B17: 2019 | C17: 31923.436 | D17: 57669.998 | E17: 36.74 | F17: 0.94 | G17: 2.494692 | H17: 47 | I17: 100 | J17: 0.70776963 | K17: 1.4 | L17: 6837.7178 | M17: 207600 | N17: 53.709807 | O17: 27.953389 | P17: =VLOOKUP(A17, imports_filtered!$A$2:$C$1000, 2, 0) -> 85.255535
A18: Belgium | B18: 2019 | C18: 64152.26 | D18: 93010.002 | E18: 29.32 | F18: 19.47 | G18: 68.237465 | H18: 383 | I18: 100 | J18: 7.959382 | K18: 2.1495597 | L18: 46591.492 | M18: 30528 | N18: 50.503887 | O18: 4.469936 | P18: =VLOOKUP(A18, imports_filtered!$A$2:$C$1000, 2, 0) -> 90.930226
A19: Belize | B19: 2019 | C19: 9883.737 | D19: 639.99999 | E19: 0.41 | F19: 0.47 | G19: 53.409092 | H19: 17 | I19: 92.72 | K19: 1.7627979 | L19: 5078.8099 | M19: 22966 | N19: 17.189877 | O19: -88.49765 | P19: =VLOOKUP(A19, imports_filtered!$A$2:$C$1000, 2, 0) -> #N/A
A20: Benin | B20: 2019 | C20: 2416.162 | D20: 7300.0002 | E20: 0.19 | F20: 0.01 | G20: 5 | H20: 108 | I20: 40.32869 | K20: 6.8656873 | L20: 1219.5155 | M20: 112622 | N20: 9.30769 | O20: 2.315834 | P20: =VLOOKUP(A20, imports_filtered!$A$2:$C$1000, 2, 0) -> 46.041641
A21: Bermuda | B21: 2019 | C21: 50639.293 | E21: 0 | F21: 0 | H21: 1281 | I21: 100 | K21: 0.45988994 | L21: 117098.45 | M21: 54 | N21: 32.299507 | O21: -64.790337 | P21: =VLOOKUP(A21, imports_filtered!$A$2:$C$1000, 2, 0) -> #N/A
A22: Bhutan | B22: 2019 | C22: 27251.602 | D22: 1050 | E22: 0 | F22: 8.95 | G22: 100 | H22: 20 | I22: 100 | K22: 5.75517 | L22: 3322.8633 | M22: 38394 | N22: 27.514162 | O22: 90.433601 | P22: =VLOOKUP(A22, imports_filtered!$A$2:$C$1000, 2, 0) -> #N/A
A23: Bosnia and Herzegovina | B23: 2019 | C23: 20694.338 | D23: 21070 | E23: 10.36 | F23: 6.31 | G23: 37.85243 | H23: 64 | I23: 100 | K23: 2.8310026 | L23: 6119.7623 | M23: 51197 | N23: 43.915886 | O23: 17.679076 | P23: =VLOOKUP(A23, imports_filtered!$A$2:$C$1000, 2, 0) -> 27.394097
A24: Botswana | B24: 2019 | C24: 9467.984 | D24: 7250 | E24: 3.05 | F24: 0.01 | G24: 0.3267974 | H24: 4 | I24: 69.95974 | K24: 2.9927376 | L24: 7203.0642 | M24: 581730 | N24: -22.328474 | O24: 24.684866 | P24: =VLOOKUP(A24, imports_filtered!$A$2:$C$1000, 2, 0) -> 33.186239
A25: Brazil | B25: 2019 | C25: 16681.945 | D25: 434299.99 | E25: 90.91 | F25: 512.59 | G25: 85.30534 | H25: 25 | I25: 99.8 | J25: 47.304844 | K25: 1.411153 | L25: 8897.553 | M25: 8515770 | N25: -14.235004 | O25: -51.92528 | P25: =VLOOKUP(A25, imports_filtered!$A$2:$C$1000, 2, 0) -> -4.0596361
A26: Bulgaria | B26: 2019 | C26: 29996.027 | D26: 39139.999 | E26: 19.75 | F26: 7.49 | G26: 54.908676 | H26: 64 | I26: 100 | J26: 9.948385 | K26: 4.0375921 | L26: 9879.2685 | M26: 110879 | N26: 42.733883 | O26: 25.48583 | P26: =VLOOKUP(A26, imports_filtered!$A$2:$C$1000, 2, 0) -> 39.323183
A27: Burkina Faso | B27: 2019 | C27: 946.95734 | D27: 5000 | E27: 1.51 | F27: 0.21 | G27: 12.209302 | H27: 76 | I27: 18.374855 | K27: 5.6881151 | L27: 796.11521 | M27: 274200 | N27: 12.238333 | O27: -1.561593 | P27: =VLOOKUP(A27, imports_filtered!$A$2:$C$1000, 2, 0) -> #N/A
A28: Burundi | B28: 2019 | C28: 309.34055 | D28: 720.00003 | E28: 0.12 | F28: 0.24 | G28: 66.666664 | H28: 463 | I28: 11.356528 | K28: 1.8424767 | L28: 228.21359 | M28: 27830 | N28: -3.373056 | O28: 29.918886 | P28: =VLOOKUP(A28, imports_filtered!$A$2:$C$1000, 2, 0) -> #N/A
A29: Cambodia | B29: 2019 | C29: 4069.4607 | D29: 16180 | E29: 3.94 | F29: 4.51 | G29: 53.372787 | H29: 95 | I29: 84 | K29: 7.0541069 | L29: 1643.1214 | M29: 181035 | N29: 12.565679 | O29: 104.99096 | P29: =VLOOKUP(A29, imports_filtered!$A$2:$C$1000, 2, 0) -> 0
A30: Cameroon | B30: 2019 | C30: 1720.2494 | D30: 9430.0003 | E30: 2.99 | F30: 5.36 | G30: 64.19161 | H30: 56 | I30: 63.48988 | K30: 3.47506 | L30: 1533.0957 | M30: 475440 | N30: 7.369722 | O30: 12.354722 | P30: =VLOOKUP(A30, imports_filtered!$A$2:$C$1000, 2, 0) -> -31.903384
A31: Canada | B31: 2019 | C31: 107980.76 | D31: 580210.02 | E31: 110.65 | F31: 421.8 | G31: 82.378334 | H31: 4 | I31: 100 | J31: 28.586376 | K31: 1.879592 | L31: 46338.341 | M31: 9984670 | N31: 56.130366 | O31: -106.34677 | P31: =VLOOKUP(A31, imports_filtered!$A$2:$C$1000, 2, 0) -> -75.769176
A32: Cayman Islands | B32: 2019 | C32: 50531.71 | E32: 0.68 | F32: 0.02 | G32: 2.857143 | H32: 274 | I32: 100 | K32: 3.8171004 | L32: 91392.643 | M32: 264 | N32: 19.3299 | O32: 81.2524 | P32: =VLOOKUP(A32, imports_filtered!$A$2:$C$1000, 2, 0) -> #N/A
A33: Central African Republic | B33: 2019 | C33: 299.18008 | D33: 239.99999 | E33: 0 | F33: 0.15 | G33: 100 | H33: 8 | I33: 14.3 | K33: 3 | L33: 467.90803 | M33: 622984 | N33: 6.611111 | O33: 20.939444 | P33: =VLOOKUP(A33, imports_filtered!$A$2:$C$1000, 2, 0) -> #N/A
A34: Chad | B34: 2019 | C34: 458.18085 | D34: 2250 | E34: 0.3 | F34: 0.01 | G34: 3.2258065 | H34: 13 | I34: 8.4 | K34: 3.2471819 | L34: 709.54004 | M34: 1284000 | N34: 15.454166 | O34: 18.732207 | P34: =VLOOKUP(A34, imports_filtered!$A$2:$C$1000, 2, 0) -> -204.99154
A35: Chile | B35: 2019 | C35: 24894.514 | D35: 91370.003 | E35: 45.16 | F35: 32.23 | G35: 41.64621 | H35: 26 | I35: 100 | J35: 24.144995 | K35: 0.94200531 | L35: 14741.714 | M35: 756096 | N35: -35.675147 | O35: -71.542969 | P35: =VLOOKUP(A35, imports_filtered!$A$2:$C$1000, 2, 0) -> 69.225887
A36: China | B36: 2019 | C36: 28277.445 | D36: 10707220 | E36: 5098.22 | F36: 2014.57 | G36: 31.672895 | H36: 153 | I36: 100 | J36: 13.51596 | K36: 5.9497142 | L36: 10143.838 | M36: 9596960 | N36: 35.86166 | O36: 104.1954 | P36: =VLOOKUP(A36, imports_filtered!$A$2:$C$1000, 2, 0) -> 22.220974
A37: Colombia | B37: 2019 | C37: 11221.787 | D37: 81040.001 | E37: 23.84 | F37: 54.31 | G37: 69.49456 | H37: 46 | I37: 99.75592 | J37: 29.890343 | K37: 3.2811168 | L37: 6424.9795 | M37: 1138910 | N37: 4.570868 | O37: -74.297333 | P37: =VLOOKUP(A37, imports_filtered!$A$2:$C$1000, 2, 0) -> -181.41411
A38: Comoros | B38: 2019 | C38: 1685.7296 | D38: 319.99999 | E38: 0.1 | F38: 0 | G38: 0 | H38: 467 | I38: 84.297775 | K38: 1.7553283 | L38: 1401.5423 | M38: 2235 | N38: -11.6455 | O38: 43.3333 | P38: =VLOOKUP(A38, imports_filtered!$A$2:$C$1000, 2, 0) -> #N/A
A39: Congo | B39: 2019 | C39: 2873.82 | E39: 2.72 | F39: 0.94 | G39: 25.68306 | H39: 18 | I39: 48.407475 | M39: 2345409 | N39: -4.1128 | O39: 13.7289 | P39: =VLOOKUP(A39, imports_filtered!$A$2:$C$1000, 2, 0) -> #N/A
A40: Costa Rica | B40: 2019 | C40: 13012.45 | D40: 8239.9998 | E40: 0.25 | F40: 11.18 | G40: 97.81277 | H40: 100 | I40: 99.71 | K40: 2.2563151 | L40: 12693.828 | M40: 51100 | N40: 9.748917 | O40: -83.753428 | P40: =VLOOKUP(A40, imports_filtered!$A$2:$C$1000, 2, 0) -> 57.963811
...

Sheet imports_filtered
A1: Country Name | B1: 2019
A2: Albania | B2: 32.231803
A3: Algeria | B3: -133.35275
A4: Angola | B4: -488.93284
A5: Argentina | B5: 2.4916771
A6: Armenia | B6: 74.170785
A7: Australia | B7: -230.54025
A8: Austria | B8: 74.476282
A9: Azerbaijan | B9: -274.41746
A10: Bahrain | B10: -53.430627
A11: Bangladesh | B11: 30.297494
A12: Belarus | B12: 85.255535
A13: Belgium | B13: 90.930226
... A20: Bulgaria | B20: 39.323183
A21: Cambodia
A22: Cameroon | B22: -31.903384
A23: Canada | B23: -75.769176
A24: Chad | B24: -204.99154
A25: Chile | B25: 69.225887
A26: China | B26: 22.220974
A27: Colombia | B27: -181.41411
A28: Congo, Rep. | B28: -511.22993
A29: Costa Rica | B29: 57.963811
A30: Cote d'Ivoire | B30: 4.6010464
A31: Croatia | B31: 57.796268
A32: Cuba | B32: 52.813625
A33: Curaçao
A34: Cyprus
A35: Czech Republic | B35: 41.0173
A36: Denmark | B36: 43.767617
A37: Dominican Republic | B37: 93.940654
A38: Ecuador | B38: -95.754232
A39: Egypt, Arab Rep. | B39: -0.53103398
A40: El Salvador | B40: 61.322795
A41: Eritrea
A42: Estonia | B42: 5.117667
A43: Eswatini | B43: 31.47877
A44: Ethiopia(excludes Eritrea) | B44: 12.044912
A45: Finland | B45: 44.40371
A46: Fm Sudan | B46: 15.655636
...

Sheet count_empty
A1: Entity | B1: Year | C1: Primary energy consumption per capita (kWh/person) | D1: Value_co2_emissions_kt_by_country | E1: Electricity from fossil fuels (TWh) | F1: Electricity from nuclear (TWh) | G1: Electricity from renewables (TWh) | H1: Low-carbon electricity (% electricity) | I1: Renewable-electricity-generating-capacity-per-capita | J1: Renewable energy share in the total final energy consumption (%) | K1: Density\n(P/Km2) | L1: Access to electricity (% of population) | M1: Access to clean fuels for cooking | N1: Renewables (% equivalent primary energy) | O1: Financial flows to developing countries (US $) | P1: gdp_growth | Q1: gdp_per_capita | R1: Energy intensity level of primary energy (MJ/$2017 PPP GDP) | S1: Land Area(Km2) | T1: Latitude | U1: Longitude
A2: =COUNTIF(energy!A:A, 0) + COUNTIF(energy!A:A, ЕПУСТО) -> 0 | B2: =COUNTIF(energy!B:B, 0) + COUNTIF(energy!B:B, ЕПУСТО) -> 0 | C2: =COUNTIF(energy!C:C, 0) + COUNTIF(energy!C:C, ЕПУСТО) -> 21 | D2: =COUNTIF(energy!D:D, 0) + COUNTIF(energy!D:D, ЕПУСТО) -> 0 | E2: =COUNTIF(energy!E:E, 0) + COUNTIF(energy!E:E, ЕПУСТО) -> 141 | F2: =COUNTIF(energy!F:F, 0) + COUNTIF(energy!F:F, ЕПУСТО) -> 2945 | G2: =COUNTIF(energy!G:G, 0) + COUNTIF(energy!G:G, ЕПУСТО) -> 639 | H2: =COUNTIF(energy!H:H, 0) + COUNTIF(energy!H:H, ЕПУСТО) -> 618 | I2: =COUNTIF(energy!I:I, 0) + COUNTIF(energy!I:I, ЕПУСТО) -> 229 | J2: =COUNTIF(energy!J:J, 0) + COUNTIF(energy!J:J, ЕПУСТО) -> 95 | K2: =COUNTIF(energy!K:K, 0) + COUNTIF(energy!K:K, ЕПУСТО) -> 0 | L2: =COUNTIF(energy!L:L, 0) + COUNTIF(energy!L:L, ЕПУСТО) -> 0 | M2: =COUNTIF(energy!M:M, 0) + COUNTIF(energy!M:M, ЕПУСТО) -> 8 | N2: =COUNTIF(energy!N:N, 0) + COUNTIF(energy!N:N, ЕПУСТО) -> 58 | O2: =COUNTIF(energy!O:O, 0) + COUNTIF(energy!O:O, ЕПУСТО) -> 25 | P2: =COUNTIF(energy!P:P, 0) + COUNTIF(energy!P:P, ЕПУСТО) -> 1 | Q2: =COUNTIF(energy!Q:Q, 0) + COUNTIF(energy!Q:Q, ЕПУСТО) -> 0 | R2: =COUNTIF(energy!R:R, 0) + COUNTIF(energy!R:R, ЕПУСТО) -> 0 | S2: =COUNTIF(energy!S:S, 0) + COUNTIF(energy!S:S, ЕПУСТО) -> 0 | T2: =COUNTIF(energy!T:T, 0) + COUNTIF(energy!T:T, ЕПУСТО) -> 0 | U2: =COUNTIF(energy!U:U, 0) + COUNTIF(energy!U:U, ЕПУСТО) -> 0
A5: =3600/20 -> 180
